<?xml version="1.0"?>
<robot xmlns:xacro="http://www.ros.org/wiki/xacro" >


    <xacro:include filename="inertial_macros.xacro"/>

    <material name="white">
        <color rgba="1 1 1 1"/>
    </material>

    <material name="orange">
        <color rgba="1 0.3 0.1 1"/>
    </material>

    <material name="blue">
        <color rgba="0.2 0.2 1 1"/>
    </material>

    <material name="black">
        <color rgba="0 0 0 1"/>
    </material>


    <!--BASE LINK -->
    <link name="base_link">

    </link>
    <joint name="base_joint" type="fixed">
        <parent link="base_link"/>
        <child link="chasis"/>
    </joint>

    <!-- CHASIS LINK -->

    <joint name="chasis_joint" type="fixed">
        <parent link="base_link"/>
        <child link="chasis"/>
        <origin xyz="0 0 0"/>
    </joint>

    <link name="chasis">
        <visual>
            <origin xyz="0 0 0"/>
            <geometry>
                <box size="1 0.6 0.3"/>
            </geometry>
            <material name="white"/>
        </visual>
        <collision>
            <origin xyz="0 0 0"/>
            <geometry>
                <box size="1 0.6 0.3"/>
            </geometry>
        </collision>
        <xacro:inertial_box mass="1" x="1" y="0.6" z="0.3">
            <origin xyz="0 0 0" rpy="0 0 0"/>
        </xacro:inertial_box>
        
    </link>
    <gazebo reference="chasis">
        <material>Gazebo/White</material>
        <mu1>0.02</mu1>
        <mu2>0.02</mu2>
    </gazebo>

    <!--FRONT LEFT WHEEL LINK-->

    <joint name="front_left_wheel_joint" type="continuous">
        <parent link="chasis"/>
        <child link="front_left_wheel"/>
        <origin xyz="0.3 -0.35 -0.15" rpy="-${pi/2} 0 0"/>
        <axis xyz="0 0 1"/>
    </joint>

    <link name="front_left_wheel">
        <visual>
            <geometry>
                <cylinder radius="0.15" length="0.1"/>
            </geometry>
            <material name="blue"/>
        </visual>
        <collision>
            <geometry>
                <cylinder radius="0.15" length="0.1"/>
            </geometry>
        </collision>
        <xacro:inertial_cylinder mass="0.1" length="0.1" radius="0.15">
            <origin xyz="0 0 0" rpy="0 0 0"/>
        </xacro:inertial_cylinder>
        
    </link>
    <gazebo reference="front_left_wheel">
        <material>Gazebo/Blue</material>
        <mu1>0.02</mu1>
        <mu2>0.02</mu2>
    </gazebo>

    <!--BACK LEFT WHEEL LINK-->

    <joint name="back_left_wheel_joint" type="continuous">
        <parent link="chasis"/>
        <child link="back_left_wheel"/>
        <origin xyz="-0.3 -0.35 -0.15" rpy="-${pi/2} 0 0"/>
        <axis xyz="0 0 1"/>
    </joint>

    <link name="back_left_wheel">
        <visual>
            <geometry>
                <cylinder radius="0.15" length="0.1"/>
            </geometry>
            <material name="blue"/>
        </visual>
        <collision>
            <geometry>
                <cylinder radius="0.15" length="0.1"/>
            </geometry>
        </collision>
        <xacro:inertial_cylinder mass="0.1" length="0.1" radius="0.15">
            <origin xyz="0 0 0" rpy="0 0 0"/>
        </xacro:inertial_cylinder>
        
    </link>
    <gazebo reference="back_left_wheel">
        <material>Gazebo/Blue</material>
        <mu1>0.02</mu1>
        <mu2>0.02</mu2>
    </gazebo>

    <!--FRONT RIGHT WHEEL LINK-->

    <joint name="front_right_wheel_joint" type="continuous">
        <parent link="chasis"/>
        <child link="front_right_wheel"/>
        <origin xyz="0.3 0.35 -0.15" rpy="-${pi/2} 0 0"/>
        <axis xyz="0 0 1"/>
    </joint>

    <link name="front_right_wheel">
        <visual>
            <geometry>
                <cylinder radius="0.15" length="0.1"/>
            </geometry>
            <material name="blue"/>
        </visual>
        <collision>
            <geometry>
                <cylinder radius="0.15" length="0.1"/>
            </geometry>
        </collision>
        <xacro:inertial_cylinder mass="0.1" length="0.1" radius="0.15">
            <origin xyz="0 0 0" rpy="0 0 0"/>
        </xacro:inertial_cylinder>
        
    </link>
    <gazebo reference="front_right_wheel">
        <material>Gazebo/Blue</material>
        <mu1>0.02</mu1>
        <mu2>0.02</mu2>
    </gazebo>

    <!--BACK RIGHT WHEEL LINK-->

    <joint name="back_right_wheel_joint" type="continuous">
        <parent link="chasis"/>
        <child link="back_right_wheel"/>
        <origin xyz="-0.3 0.35 -0.15" rpy="-${pi/2} 0 0"/>
        <axis xyz="0 0 1"/>
    </joint>

    <link name="back_right_wheel">
        <visual>
            <geometry>
                <cylinder radius="0.15" length="0.1"/>
            </geometry>
            <material name="blue"/>
        </visual>
        <collision>
            <geometry>
                <cylinder radius="0.15" length="0.1"/>
            </geometry>
        </collision>
        <xacro:inertial_cylinder mass="0.1" length="0.1" radius="0.15">
            <origin xyz="0 0 0" rpy="0 0 0"/>
        </xacro:inertial_cylinder>
        
    </link>
    <gazebo reference="back_right_wheel">
        <material>Gazebo/Blue</material>
        <mu1>0.02</mu1>
        <mu2>0.02</mu2>
    </gazebo>
</robot>